Workbook

Sheet サマリ
A1: イベント申込システム テスト結果表
A2: テストケースは docs/40_テスト/ のテスト仕様書（41・42・43）と同じ内容である。ルールは 40_テスト計画書 に従う。
A4: テスト開始日 | B4: 46302
A5: 実施者 | B5: 佐々木
A6: 対象 | B6: この結果表と同じコミットのソースコード
A7: ブラウザ | B7: Google Chrome
A8: データベース | B8: MySQL 8.0（手動テスト）、H2（自動テスト）
A10: レベル | B10: 内容 | C10: 総数 | D10: OK | E10: NG | F10: 保留 | G10: 対象外 | H10: 未実施 | I10: 消化率
A11: UT | B11: 単体テスト | C11: 179 | D11: =COUNTIF(UT!M2:M180,"OK") | E11: =COUNTIF(UT!M2:M180,"NG") | F11: =COUNTIF(UT!M2:M180,"保留") | G11: =COUNTIF(UT!M2:M180,"対象外") | H11: =C11-SUM(D11:G11) | I11: =IF(C11=0,0,(D11+E11+G11)/C11)
A12: IT | B12: 結合テスト（API結合） | C12: 211 | D12: =COUNTIF(IT_API結合!M2:M212,"OK") | E12: =COUNTIF(IT_API結合!M2:M212,"NG") | F12: =COUNTIF(IT_API結合!M2:M212,"保留") | G12: =COUNTIF(IT_API結合!M2:M212,"対象外") | H12: =C12-SUM(D12:G12) | I12: =IF(C12=0,0,(D12+E12+G12)/C12)
A13: IT | B13: 結合テスト（画面結合） | C13: 132 | D13: =COUNTIF(IT_画面結合!M2:M133,"OK") | E13: =COUNTIF(IT_画面結合!M2:M133,"NG") | F13: =COUNTIF(IT_画面結合!M2:M133,"保留") | G13: =COUNTIF(IT_画面結合!M2:M133,"対象外") | H13: =C13-SUM(D13:G13) | I13: =IF(C13=0,0,(D13+E13+G13)/C13)
A14: ST | B14: 総合テスト（業務シナリオ・非機能） | C14: 94 | D14: =COUNTIF(ST!M2:M95,"OK") | E14: =COUNTIF(ST!M2:M95,"NG") | F14: =COUNTIF(ST!M2:M95,"保留") | G14: =COUNTIF(ST!M2:M95,"対象外") | H14: =C14-SUM(D14:G14) | I14: =IF(C14=0,0,(D14+E14+G14)/C14)
A15: 合計 | C15: =SUM(C11:C14) | D15: =SUM(D11:D14) | E15: =SUM(E11:E14) | F15: =SUM(F11:F14) | G15: =SUM(G11:G14) | H15: =SUM(H11:H14) | I15: =IF(C15=0,0,(D15+E15+G15)/C15)
A17: 【記入ルール】（40_テスト計画書 7章・8章）
A18: ・黄色の見出しの列（結果〜再テスト日）を記入する。それ以外の列はテスト仕様書の内容であり、変更しない。
A19: ・結果：期待結果（データベースの状態を含む）をすべて満たせば OK、1つでも満たさなければ NG。前提を作れない・判断できない場合は 保留。
A20: ・実際の結果・備考：NG・保留・対象外のときは必ず記入する。OKのときも、確認した値（ステータス、件数等）を書くとよい。
A21: ・証跡：ファイル名をテストIDで始め、docs/40_テスト/evidence/ の UT・IT・ST のフォルダに保存し、そのファイル名を記入する。
A22: 画面の証跡は、アドレスバー（URL）と日時が分かるものを含めて撮る。データベースの証跡は、SELECT文と結果を残す。
A23: ・不具合Issue：NGのときにGitHubのIssueを起票し、番号（例 #12）を記入する。「不具合一覧」シートにも1行追加する。
A24: ・再テスト：修正の取り込み後に同じテストケースを再実施し、再テスト結果・再テスト日を記入する（最初の結果は消さない）。
A25: ・自動テストの行は、テストの実行レポートをもとに記入済みである。自動テストを再実行した場合は、実施日と証跡を更新する。
A26: ・消化率＝（OK＋NG＋対象外）÷総数

Sheet UT
A1: ID | B1: 対象 | C1: 区分 | D1: 確認する内容 | E1: 前提 | F1: 操作・入力 | G1: 期待結果 | H1: 期待結果（データベース） | I1: 確認SQL | J1: 根拠 | K1: 実施方法 | L1: 自動テスト | M1: 結果 | N1: 実施日 | O1: 実施者 | P1: 実際の結果・備考 | Q1: 証跡 | R1: 不具合Issue | S1: 再テスト結果 | T1: 再テスト日
A2: UT-APP-N01 | B2: ApplicationService（申込・キャンセル・当日受付） | C2: 正常系 | D2: 定員に余裕があれば受付済で申込できる | E2: 区分なし、受付済数＜定員 | F2: apply | G2: 申込状況＝受付済で登録される | H2: - | I2: - | J2: R-02 | K2: 自動 | L2: apply_正常系_定員に余裕があれば受付済で申込できる | M2: OK | N2: 46302 | O2: 佐々木（Claude Code） | P2: 自動テスト成功 | Q2: evidence/UT/UT_バックエンド_結果一覧_20261007.txt
A3: UT-APP-N02 | B3: ApplicationService（申込・キャンセル・当日受付） | C3: 正常系 | D3: 定員に達していればキャンセル待ちで登録される | E3: 区分なし、受付済数＝定員 | F3: apply | G3: 申込状況＝キャンセル待ちで登録される（エラーにならない） | H3: - | I3: - | J3: R-02 | K3: 自動 | L3: apply_機能追加_定員に達していればキャンセル待ちで登録される | M3: OK | N3: 46302 | O3: 佐々木（Claude Code） | P3: 自動テスト成功 | Q3: evidence/UT/UT_バックエンド_結果一覧_20261007.txt
A4: UT-APP-N03 | B4: ApplicationService（申込・キャンセル・当日受付） | C4: 正常系 | D4: キャンセル済の申込のみなら再申込できる | E4: 同一イベントにキャンセル済の申込のみある | F4: apply | G4: 再申込でき、新しい申込が登録される | H4: - | I4: - | J4: 10_要件定義書 7章「二重申込の防止」 | K4: 自動 | L4: apply_正常系_キャンセル済の申込のみなら再申込できる | M4: OK | N4: 46302 | O4: 佐々木（Claude Code） | P4: 自動テスト成功 | Q4: evidence/UT/UT_バックエンド_結果一覧_20261007.txt
A5: UT-APP-N04 | B5: ApplicationService（申込・キャンセル・当日受付） | C5: 正常系 | D5: 区分の定員に余裕があれば受付済で申込できる | E5: 区分あり、指定区分の受付済数＜区分定員 | F5: apply | G5: 申込状況＝受付済、ticketTypeIdが設定される | H5: - | I5: - | J5: R-02 | K5: 自動 | L5: apply_機能追加_区分の定員に余裕があれば受付済で申込できる | M5: OK | N5: 46302 | O5: 佐々木（Claude Code） | P5: 自動テスト成功 | Q5: evidence/UT/UT_バックエンド_結果一覧_20261007.txt
A6: UT-APP-N05 | B6: ApplicationService（申込・キャンセル・当日受付） | C6: 正常系 | D6: 区分の定員に達していればキャンセル待ちで登録される | E6: 区分あり、指定区分の受付済数＝区分定員 | F6: apply | G6: 申込状況＝キャンセル待ち | H6: - | I6: - | J6: R-02 | K6: 自動 | L6: apply_機能追加_区分の定員に達していればキャンセル待ちで登録される | M6: OK | N6: 46302 | O6: 佐々木（Claude Code） | P6: 自動テスト成功 | Q6: evidence/UT/UT_バックエンド_結果一覧_20261007.txt
A7: UT-APP-N06 | B7: ApplicationService（申込・キャンセル・当日受付） | C7: 正常系 | D7: 現在時刻が申込締切ちょうどなら受付中と判定される | E7: 現在時刻＝申込締切（開催日時より前） | F7: apply | G7: 受付される（締切「以前」は受付） | H7: - | I7: - | J7: R-01 | K7: 自動 | L7: apply_境界_現在時刻が申込締切ちょうどなら受付中と判定される | M7: OK | N7: 46302 | O7: 佐々木（Claude Code） | P7: 自動テスト成功 | Q7: evidence/UT/UT_バックエンド_結果一覧_20261007.txt
A8: UT-APP-N07 | B8: ApplicationService（申込・キャンセル・当日受付） | C8: 正常系 | D8: 受付済かつ開催前なら取消できる | E8: 本人・受付済・開催前 | F8: cancel | G8: 申込状況＝キャンセル済に更新される | H8: - | I8: - | J8: R-04 | K8: 自動 | L8: cancel_正常系_受付済かつ開催前なら取消できる | M8: OK | N8: 46302 | O8: 佐々木（Claude Code） | P8: 自動テスト成功 | Q8: evidence/UT/UT_バックエンド_結果一覧_20261007.txt
A9: UT-APP-N08 | B9: ApplicationService（申込・キャンセル・当日受付） | C9: 正常系 | D9: 受付済のキャンセルでキャンセル待ちが繰り上がる | E9: 受付済をキャンセル、同一イベントにキャンセル待ちが複数 | F9: cancel | G9: 申込日時が最も古いキャンセル待ち1件だけが受付済になる | H9: - | I9: - | J9: R-05 | K9: 自動 | L9: cancel_機能追加_受付済のキャンセルでキャンセル待ちが繰り上がる | M9: OK | N9: 46302 | O9: 佐々木（Claude Code） | P9: 自動テスト成功 | Q9: evidence/UT/UT_バックエンド_結果一覧_20261007.txt
A10: UT-APP-N09 | B10: ApplicationService（申込・キャンセル・当日受付） | C10: 正常系 | D10: キャンセル待ちの申込も取消できる | E10: キャンセル待ちをキャンセル | F10: cancel | G10: キャンセル済になり、繰り上げは発生しない | H10: - | I10: - | J10: R-04, R-05 | K10: 自動 | L10: cancel_機能追加_キャンセル待ちの申込も取消できる | M10: OK | N10: 46302 | O10: 佐々木（Claude Code） | P10: 自動テスト成功 | Q10: evidence/UT/UT_バックエンド_結果一覧_20261007.txt
A11: UT-APP-N10 | B11: ApplicationService（申込・キャンセル・当日受付） | C11: 正常系 | D11: 区分単位でキャンセル待ちが繰り上がる | E11: 区分ありで受付済をキャンセル | F11: cancel | G11: 同一区分のキャンセル待ちのみ繰り上がる（他区分は変化しない） | H11: - | I11: - | J11: R-05 | K11: 自動 | L11: cancel_機能追加_区分単位でキャンセル待ちが繰り上がる | M11: OK | N11: 46302 | O11: 佐々木（Claude Code） | P11: 自動テスト成功 | Q11: evidence/UT/UT_バックエンド_結果一覧_20261007.txt
A12: UT-APP-N11 | B12: ApplicationService（申込・キャンセル・当日受付） | C12: 正常系 | D12: 区分単位でキャンセル待ちの順位が計算される | E12: 区分ありでキャンセル待ちが複数 | F12: myApplications | G12: waitlistRankが同一区分内の「自分より古いキャンセル待ち件数＋1」になる | H12: - | I12: - | J12: 10_要件定義書 7章「キャンセル待ち順位」 | K12: 自動 | L12: myApplications_機能追加_区分単位でキャンセル待ちの順位が計算される | M12: OK | N12: 46302 | O12: 佐々木（Claude Code） | P12: 自動テスト成功 | Q12: evidence/UT/UT_バックエンド_結果一覧_20261007.txt
A13: UT-APP-N12 | B13: ApplicationService（申込・キャンセル・当日受付） | C13: 正常系 | D13: 受付済の申込はwaitlistRankがNULL | E13: 受付済の申込 | F13: myApplications | G13: waitlistRankがNULL | H13: - | I13: - | J13: AP-031 | K13: 自動 | L13: myApplications_正常系_受付済の申込はwaitlistRankがNULL | M13: OK | N13: 46302 | O13: 佐々木（Claude Code） | P13: 自動テスト成功 | Q13: evidence/UT/UT_バックエンド_結果一覧_20261007.txt
... A180: UT-APP-E15 | B180: ApplicationService（申込・キャンセル・当日受付） | C180: 異常系 | D180: 区分の無いイベントに区分を指定すると指定された区分が見つかりませんで拒否される | E180: 区分なしイベントでticketTypeIdを指定 | F180: apply | G180: NotFoundException「指定された区分が見つかりません」（E-B-005） | H180: - | I180: - | J180: 32_処理詳細設計書 4章 AP-030 No.7 | K180: 自動 | L180: apply_異常系_区分の無いイベントに区分を指定すると指定された区分が見つかりませんで拒否される | M180: OK | N180: 46304 | O180: 佐々木（Claude Code） | P180: 自動テスト成功（Issue #18 の修正で追加） | Q180: evidence/UT/UT_バックエンド_結果一覧_20261009.txt

Sheet IT_API結合
A1: ID | B1: 対象 | C1: 区分 | D1: 確認する内容 | E1: 前提 | F1: 操作・入力 | G1: 期待結果 | H1: 期待結果（データベース） | I1: 確認SQL | J1: 根拠 | K1: 実施方法 | L1: 自動テスト | M1: 結果 | N1: 実施日 | O1: 実施者 | P1: 実際の結果・備考 | Q1: 証跡 | R1: 不具合Issue | S1: 再テスト結果 | T1: 再テスト日
A2: IT-CMN-N01 | B2: 認証・リクエスト形式 | C2: 正常系 | D2: ログインは認証情報なしで呼べる | E2: - | F2: X-User-IdなしでPOST /api/login（正しいメールアドレスとパスワード） | G2: 200（401にならない） | H2: -（参照のみ） | I2: - | J2: 23_API基本設計書 2.1 | K2: 手動 | M2: OK | N2: 46303 | O2: 佐々木 | Q2: 45_テストエビデンス_API結合.xlsx／共通
A3: IT-CMN-N02 | B3: 認証・リクエスト形式 | C3: 正常系 | D3: 利用者登録は認証情報なしで呼べる | E3: 未登録のメールアドレス | F3: X-User-IdなしでPOST /api/users | G3: 201（401にならない） | H3: usersに1行追加される | I3: 【操作の前と後に実行し、期待結果のとおりであることを確認する】 SELECT id, name, email, role_code, password_hash, anonymized_at, updated_at FROM users ORDER BY id; | J3: 23_API基本設計書 2.1 | K3: 手動 | M3: OK | N3: 46303 | O3: 佐々木 | Q3: 45_テストエビデンス_API結合.xlsx／共通
A4: IT-CMN-N03 | B4: 認証・リクエスト形式 | C4: 正常系 | D4: 稼働確認は認証情報なしで呼べる | E4: - | F4: X-User-IdなしでGET /api/ping | G4: 200（401にならない） | H4: -（参照のみ） | I4: - | J4: 23_API基本設計書 2.1 | K4: 手動 | M4: OK | N4: 46303 | O4: 佐々木 | Q4: 45_テストエビデンス_API結合.xlsx／共通
A5: IT-CMN-N04 | B5: 認証・リクエスト形式 | C5: 正常系 | D5: Swagger UIは認証の対象外である | E5: - | F5: X-User-IdなしでGET /swagger-ui.html | G5: 302で/swagger-ui/index.htmlへ転送され、転送先が200（401にならない） | H5: -（参照のみ） | I5: - | J5: 33_共通詳細設計書 5.1 | K5: 手動 | M5: OK | N5: 46303 | O5: 佐々木 | Q5: 45_テストエビデンス_API結合.xlsx／共通
A6: IT-CMN-N05 | B6: 認証・リクエスト形式 | C6: 正常系 | D6: OpenAPIの定義は認証の対象外である | E6: - | F6: X-User-IdなしでGET /v3/api-docs | G6: 200 | H6: -（参照のみ） | I6: - | J6: 33_共通詳細設計書 5.1 | K6: 手動 | M6: OK | N6: 46303 | O6: 佐々木 | Q6: 45_テストエビデンス_API結合.xlsx／共通
A7: IT-CMN-N06 | B7: 認証・リクエスト形式 | C7: 正常系 | D7: リクエストに定義されていない項目は無視される | E7: 未登録のメールアドレス | F7: POST /api/usersの本文に"roleCode": 2を加えて送る | G7: 201、roleCodeが1（一般利用者） | H7: 登録された行のusers.role_codeが1 | I7: 【操作の前と後に実行し、期待結果のとおりであることを確認する】 SELECT id, name, email, role_code, password_hash, anonymized_at, updated_at FROM users ORDER BY id; | J7: 23_API基本設計書 2.6 | K7: 手動 | M7: OK | N7: 46303 | O7: 佐々木 | Q7: 45_テストエビデンス_API結合.xlsx／共通
A8: IT-CMN-E01 | B8: 認証・リクエスト形式 | C8: 異常系 | D8: 認証情報が無いと認証エラーになる | E8: - | F8: X-User-IdなしでGET /api/events | G8: 401「認証が必要です」（E-A-001） | H8: -（参照のみ） | I8: - | J8: 33_共通詳細設計書 5.2 | K8: 手動 | M8: OK | N8: 46303 | O8: 佐々木 | Q8: 45_テストエビデンス_API結合.xlsx／共通
A9: IT-CMN-E02 | B9: 認証・リクエスト形式 | C9: 異常系 | D9: 利用者IDが数値でないと認証エラーになる | E9: - | F9: X-User-Id: abcでGET /api/events | G9: 401「認証が必要です」（E-A-001） | H9: -（参照のみ） | I9: - | J9: 33_共通詳細設計書 5.2 | K9: 手動 | M9: OK | N9: 46303 | O9: 佐々木 | Q9: 45_テストエビデンス_API結合.xlsx／共通
A10: IT-CMN-E03 | B10: 認証・リクエスト形式 | C10: 異常系 | D10: 存在しない利用者IDは認証エラーになる | E10: - | F10: X-User-Id: 9999でGET /api/events | G10: 401「認証が必要です」（E-A-001） | H10: -（参照のみ） | I10: - | J10: 33_共通詳細設計書 5.2 | K10: 手動 | M10: OK | N10: 46303 | O10: 佐々木 | Q10: 45_テストエビデンス_API結合.xlsx／共通
A11: IT-CMN-E04 | B11: 認証・リクエスト形式 | C11: 異常系 | D11: 退会済みの利用者IDは認証エラーになる | E11: 退会済みの利用者 | F11: 退会済みの利用者のIDをX-User-Idに指定してGET /api/events | G11: 401「認証が必要です」（E-A-001） | H11: -（参照のみ） | I11: - | J11: 33_共通詳細設計書 5.2 | K11: 自動 | L11: ap013_退会済みの利用者は以後のリクエストで認証エラーになる | M11: OK | N11: 46302 | O11: 佐々木（Claude Code） | P11: 自動テスト成功 | Q11: evidence/IT/IT_API結合_結果一覧_20261007.txt
A12: IT-CMN-E05 | B12: 認証・リクエスト形式 | C12: 異常系 | D12: 不正なJSONはリクエスト形式エラーになる | E12: - | F12: 一般ユーザー（ID=1）でPOST /api/favoritesの本文に{だけを送る | G12: 400「リクエストの形式が不正です」（E-V-022） | H12: favoritesは変更されない | I12: 【操作の前と後に実行し、結果が同じことを確認する】 SELECT * FROM favorites ORDER BY id; | J12: 33_共通詳細設計書 3.1 | K12: 手動 | M12: OK | N12: 46303 | O12: 佐々木 | Q12: 45_テストエビデンス_API結合.xlsx／共通
A13: IT-CMN-E06 | B13: 認証・リクエスト形式 | C13: 異常系 | D13: パスの型が不正だとリクエスト形式エラーになる | E13: - | F13: 一般ユーザー（ID=1）でGET /api/events/abc | G13: 400「パラメータの形式が不正です」（E-V-023） | H13: -（参照のみ） | I13: - | J13: 33_共通詳細設計書 3.1 | K13: 手動 | M13: OK | N13: 46303 | O13: 佐々木 | Q13: 45_テストエビデンス_API結合.xlsx／共通
A14: IT-CMN-E07 | B14: 認証・リクエスト形式 | C14: 異常系 | D14: 権限エラーは入力エラーより優先される | E14: - | F14: 一般ユーザー（ID=1）でPOST /api/eventsにnameが空の本文を送る | G14: 403「権限がありません」（E-A-002）。400にはならない | H14: eventsは変更されない | I14: 【操作の前と後に実行し、結果が同じことを確認する】 SELECT * FROM events ORDER BY id; | J14: 23_API基本設計書 2.5 | K14: 手動 | M14: OK | N14: 46303 | O14: 佐々木 | Q14: 45_テストエビデンス_API結合.xlsx／共通
A15: IT-AP010-N01 | B15: AP-010 ログイン POST /api/login | C15: 正常系 | D15: 正しいメールアドレスとパスワードでログインできる | E15: TD-00 | F15: {"email":"admin@example.com","password":"Test1234"} | G15: 200、userId=2、roleCode=2、roleName=「管理者」 | H15: -（参照のみ） | I15: - | J15: AP-010、R-22 | K15: 自動 | L15: ap010_正しいパスワードでログインでき利用者区分のコードと表示名が返る | M15: OK | N15: 46302 | O15: 佐々木（Claude Code） | P15: 自動テスト成功 | Q15: evidence/IT/IT_API結合_結果一覧_20261007.txt
A16: IT-AP010-N02 | B16: AP-010 ログイン POST /api/login | C16: 正常系 | D16: メールアドレスの前後の空白と大文字は正規化される | E16: TD-00 | F16: {"email":" ADMIN@example.com ","password":"Test1234"} | G16: 200、userId=2 | H16: -（参照のみ） | I16: - | J16: 24_方式設計書 4.3 | K16: 自動 | L16: ap010_前後に空白のあるメールアドレスでもログインできる | M16: OK | N16: 46302 | O16: 佐々木（Claude Code） | P16: 自動テスト成功 | Q16: evidence/IT/IT_API結合_結果一覧_20261007.txt
A17: IT-AP010-N03 | B17: AP-010 ログイン POST /api/login | C17: 正常系 | D17: 応答にパスワードが含まれない | E17: TD-00 | F17: 正しいメールアドレスとパスワードでログインする | G17: 200。応答にpassword・passwordHashの項目が無い | H17: -（参照のみ） | I17: - | J17: 23_API基本設計書 2.10 | K17: 手動 | M17: OK | N17: 46303 | O17: 佐々木 | Q17: 45_テストエビデンス_API結合.xlsx／AP-010
A18: IT-AP010-E01 | B18: AP-010 ログイン POST /api/login | C18: 異常系 | D18: パスワードが一致しないとログインできない | E18: TD-00 | F18: {"email":"admin@example.com","password":"Wrong1234"} | G18: 401「ログインできませんでした。入力内容をご確認のうえ、初めてご利用の場合は新規登録してください」（E-A-006） | H18: -（参照のみ） | I18: - | J18: R-22 | K18: 自動 | L18: ap010_パスワードが一致しなければ401になる | M18: OK | N18: 46302 | O18: 佐々木（Claude Code） | P18: 自動テスト成功 | Q18: evidence/IT/IT_API結合_結果一覧_20261007.txt
A19: IT-AP010-E02 | B19: AP-010 ログイン POST /api/login | C19: 異常系 | D19: 未登録のメールアドレスではログインできない（パスワード不一致と同じ文言） | E19: - | F19: {"email":"nobody@example.com","password":"Test1234"} | G19: 401「ログインできませんでした。入力内容をご確認のうえ、初めてご利用の場合は新規登録してください」（E-A-006） | H19: -（参照のみ） | I19: - | J19: R-22、24_方式設計書 3.5 | K19: 自動 | L19: ap010_未登録のメールアドレスはパスワード不一致と同じ401になる | M19: OK | N19: 46302 | O19: 佐々木（Claude Code） | P19: 自動テスト成功 | Q19: evidence/IT/IT_API結合_結果一覧_20261007.txt
A20: IT-AP010-E03 | B20: AP-010 ログイン POST /api/login | C20: 異常系 | D20: 退会済みの利用者は、退会前のメールアドレスとパスワードでログインできない | E20: 退会済みの利用者（退会前はgeneral@example.com） | F20: {"email":"general@example.com","password":"Test1234"} | G20: 401「ログインできませんでした。入力内容をご確認のうえ、初めてご利用の場合は新規登録してください」（E-A-006） | H20: -（参照のみ） | I20: - | J20: R-22、R-24 | K20: 自動 | L20: ap013_退会後は元のメールアドレスとパスワードでログインできない | M20: OK | N20: 46302 | O20: 佐々木（Claude Code） | P20: 自動テスト成功 | Q20: evidence/IT/IT_API結合_結果一覧_20261007.txt
A21: IT-AP010-E04 | B21: AP-010 ログイン POST /api/login | C21: 異常系 | D21: メールアドレスが未入力だと入力エラーになる | E21: - | F21: {"email":"","password":"Test1234"} | G21: 400、errors[]にemail「メールアドレスを入力してください」（E-V-001） | H21: -（参照のみ） | I21: - | J21: E-V-001 | K21: 手動 | M21: OK | N21: 46303 | O21: 佐々木 | Q21: 45_テストエビデンス_API結合.xlsx／AP-010
A22: IT-AP010-E05 | B22: AP-010 ログイン POST /api/login | C22: 異常系 | D22: メールアドレスの形式が不正だと入力エラーになる | E22: - | F22: {"email":"abc","password":"Test1234"} | G22: 400、errors[]にemail「メールアドレスの形式が正しくありません」（E-V-001） | H22: -（参照のみ） | I22: - | J22: E-V-001 | K22: 手動 | M22: OK | N22: 46303 | O22: 佐々木 | Q22: 45_テストエビデンス_API結合.xlsx／AP-010
A23: IT-AP010-E06 | B23: AP-010 ログイン POST /api/login | C23: 異常系 | D23: パスワードが未入力だと入力エラーになる | E23: - | F23: {"email":"admin@example.com"} | G23: 400、errors[]にpassword「パスワードを入力してください」（E-V-024） | H23: -（参照のみ） | I23: - | J23: E-V-024 | K23: 自動 | L23: ap010_パスワード未入力は400になる | M23: OK | N23: 46302 | O23: 佐々木（Claude Code） | P23: 自動テスト成功 | Q23: evidence/IT/IT_API結合_結果一覧_20261007.txt
A24: IT-AP011-N01 | B24: AP-011 利用者登録 POST /api/users | C24: 正常系 | D24: 未登録のメールアドレスで登録できる | E24: 未登録のメールアドレス | F24: 名前・メールアドレス・パスワードTest1234 | G24: 201、roleCode=1、roleName=「一般利用者」。応答にパスワードが含まれない | H24: usersに1行追加される。role_code=1。password_hashは入力値と異なる値（ハッシュ値） | I24: - | J24: AP-011、24_方式設計書 3.1 | K24: 自動 | L24: ap011_パスワードはハッシュ化して保存される | M24: OK | N24: 46302 | O24: 佐々木（Claude Code） | P24: 自動テスト成功 | Q24: evidence/IT/IT_API結合_結果一覧_20261007.txt
A25: IT-AP011-N02 | B25: AP-011 利用者登録 POST /api/users | C25: 正常系 | D25: メールアドレスは正規化して保存される | E25: 未登録のメールアドレス | F25: メールアドレスを" New-User@Example.com "として登録する | G25: 201、email=new-user@example.com | H25: users.emailがnew-user@example.com | I25: - | J25: 24_方式設計書 4.3 | K25: 自動 | L25: ap011_前後に空白のあるメールアドレスは正規化して登録される | M25: OK | N25: 46302 | O25: 佐々木（Claude Code） | P25: 自動テスト成功 | Q25: evidence/IT/IT_API結合_結果一覧_20261007.txt
A26: IT-AP011-N03 | B26: AP-011 利用者登録 POST /api/users | C26: 正常系 | D26: 名前は100文字まで登録できる（上限） | E26: 未登録のメールアドレス | F26: 名前を100文字にして登録する | G26: 201 | H26: usersに1行追加される | I26: 【操作の前と後に実行し、期待結果のとおりであることを確認する】 SELECT id, name, email, role_code, password_hash, anonymized_at, updated_at FROM users ORDER BY id; | J26: E-V-002 | K26: 手動 | M26: OK | N26: 46303 | O26: 佐々木 | Q26: 45_テストエビデンス_API結合.xlsx／AP-011
A27: IT-AP011-N04 | B27: AP-011 利用者登録 POST /api/users | C27: 正常系 | D27: パスワードは8文字で登録できる（下限） | E27: 未登録のメールアドレス | F27: パスワードをAbcdef12（8文字）にして登録する | G27: 201 | H27: usersに1行追加される | I27: 【操作の前と後に実行し、期待結果のとおりであることを確認する】 SELECT id, name, email, role_code, password_hash, anonymized_at, updated_at FROM users ORDER BY id; | J27: R-21 | K27: 手動 | M27: OK | N27: 46303 | O27: 佐々木 | Q27: 45_テストエビデンス_API結合.xlsx／AP-011
A28: IT-AP011-N05 | B28: AP-011 利用者登録 POST /api/users | C28: 正常系 | D28: パスワードは72文字で登録できる（上限） | E28: 未登録のメールアドレス | F28: 英字と数字を含む72文字のパスワードで登録する | G28: 201 | H28: usersに1行追加される | I28: 【操作の前と後に実行し、期待結果のとおりであることを確認する】 SELECT id, name, email, role_code, password_hash, anonymized_at, updated_at FROM users ORDER BY id; | J28: R-21 | K28: 手動 | M28: OK | N28: 46303 | O28: 佐々木 | Q28: 45_テストエビデンス_API結合.xlsx／AP-011
A29: IT-AP011-E01 | B29: AP-011 利用者登録 POST /api/users | C29: 異常系 | D29: 登録済みのメールアドレスは登録できない（重複を直接伝えない文言） | E29: TD-00 | F29: メールアドレスをgeneral@example.comとして登録する | G29: 400「この内容では登録できませんでした。ログインをお試しください」（E-B-015） | H29: usersの行数は変わらない | I29: 【操作の前と後に実行し、結果が同じことを確認する】 SELECT * FROM users ORDER BY id; | J29: R-15、24_方式設計書 3.5 | K29: 手動 | M29: OK | N29: 46303 | O29: 佐々木 | Q29: 45_テストエビデンス_API結合.xlsx／AP-011
A30: IT-AP011-E02 | B30: AP-011 利用者登録 POST /api/users | C30: 異常系 | D30: 空白・大文字だけが異なるメールアドレスも重複として拒否される | E30: TD-00 | F30: メールアドレスを" GENERAL@example.com "として登録する | G30: 400（E-B-015）。形式エラーにはならない | H30: usersの行数は変わらない | I30: - | J30: 24_方式設計書 4.3 | K30: 自動 | L30: ap011_登録済みのメールアドレスに空白を付けても重複として拒否される | M30: OK | N30: 46302 | O30: 佐々木（Claude Code） | P30: 自動テスト成功 | Q30: evidence/IT/IT_API結合_結果一覧_20261007.txt
A31: IT-AP011-E03 | B31: AP-011 利用者登録 POST /api/users | C31: 異常系 | D31: 名前が101文字だと入力エラーになる（上限超過） | E31: 未登録のメールアドレス | F31: 名前を101文字にして登録する | G31: 400、errors[]にname「100文字以内で入力してください」（E-V-002） | H31: usersの行数は変わらない | I31: 【操作の前と後に実行し、結果が同じことを確認する】 SELECT * FROM users ORDER BY id; | J31: E-V-002 | K31: 手動 | M31: OK | N31: 46303 | O31: 佐々木 | Q31: 45_テストエビデンス_API結合.xlsx／AP-011
A32: IT-AP011-E04 | B32: AP-011 利用者登録 POST /api/users | C32: 異常系 | D32: 名前が見えない文字だけだと入力エラーになる | E32: 未登録のメールアドレス | F32: 名前をゼロ幅スペース（U+200B）1文字にして登録する | G32: 400、errors[]にname（E-V-002） | H32: usersの行数は変わらない | I32: 【操作の前と後に実行し、結果が同じことを確認する】 SELECT * FROM users ORDER BY id; | J32: 24_方式設計書 4.3 | K32: 手動 | M32: OK | N32: 46303 | O32: 佐々木 | Q32: 45_テストエビデンス_API結合.xlsx／AP-011
A33: IT-AP011-E05 | B33: AP-011 利用者登録 POST /api/users | C33: 異常系 | D33: パスワードが8文字未満だと入力エラーになる（下限未満） | E33: 未登録のメールアドレス | F33: パスワードをShort1にして登録する | G33: 400、errors[]にpassword「パスワードは8文字以上72文字以下で、英字と数字をそれぞれ1文字以上含めてください」（E-V-025） | H33: usersの行数は変わらない | I33: - | J33: R-21 | K33: 自動 | L33: ap011_8文字未満のパスワードでは登録できない | M33: OK | N33: 46302 | O33: 佐々木（Claude Code） | P33: 自動テスト成功 | Q33: evidence/IT/IT_API結合_結果一覧_20261007.txt
A34: IT-AP011-E06 | B34: AP-011 利用者登録 POST /api/users | C34: 異常系 | D34: パスワードが英字だけだと入力エラーになる | E34: 未登録のメールアドレス | F34: パスワードをonlylettersにして登録する | G34: 400、errors[]にpassword「パスワードは8文字以上72文字以下で、英字と数字をそれぞれ1文字以上含めてください」（E-V-025） | H34: usersの行数は変わらない | I34: - | J34: R-21 | K34: 自動 | L34: ap011_英字だけのパスワードでは登録できない | M34: OK | N34: 46302 | O34: 佐々木（Claude Code） | P34: 自動テスト成功 | Q34: evidence/IT/IT_API結合_結果一覧_20261007.txt
A35: IT-AP011-E07 | B35: AP-011 利用者登録 POST /api/users | C35: 異常系 | D35: パスワードが数字だけだと入力エラーになる | E35: 未登録のメールアドレス | F35: パスワードを12345678にして登録する | G35: 400、errors[]にpassword「パスワードは8文字以上72文字以下で、英字と数字をそれぞれ1文字以上含めてください」（E-V-025） | H35: usersの行数は変わらない | I35: - | J35: R-21 | K35: 自動 | L35: ap011_数字だけのパスワードでは登録できない | M35: OK | N35: 46302 | O35: 佐々木（Claude Code） | P35: 自動テスト成功 | Q35: evidence/IT/IT_API結合_結果一覧_20261007.txt
A36: IT-AP011-E08 | B36: AP-011 利用者登録 POST /api/users | C36: 異常系 | D36: パスワードが73文字だと入力エラーになる（上限超過） | E36: 未登録のメールアドレス | F36: 英字と数字を含む73文字のパスワードで登録する | G36: 400、errors[]にpassword「パスワードは8文字以上72文字以下で、英字と数字をそれぞれ1文字以上含めてください」（E-V-025） | H36: usersの行数は変わらない | I36: 【操作の前と後に実行し、結果が同じことを確認する】 SELECT * FROM users ORDER BY id; | J36: R-21 | K36: 手動 | M36: OK | N36: 46303 | O36: 佐々木 | Q36: 45_テストエビデンス_API結合.xlsx／AP-011
A37: IT-AP011-E09 | B37: AP-011 利用者登録 POST /api/users | C37: 異常系 | D37: パスワードが未入力だと入力エラーになる | E37: 未登録のメールアドレス | F37: passwordを指定せずに登録する | G37: 400、errors[]にpassword「パスワードは8文字以上72文字以下で、英字と数字をそれぞれ1文字以上含めてください」（E-V-025） | H37: usersの行数は変わらない | I37: 【操作の前と後に実行し、結果が同じことを確認する】 SELECT * FROM users ORDER BY id; | J37: E-V-025 | K37: 手動 | M37: OK | N37: 46303 | O37: 佐々木 | Q37: 45_テストエビデンス_API結合.xlsx／AP-011
A38: IT-AP012-N01 | B38: AP-012 パスワード変更 PUT /api/my/password | C38: 正常系 | D38: 現在のパスワードが正しければ変更できる | E38: TD-00 | F38: 一般ユーザー（ID=1）で{"currentPassword":"Test1234","newPassword":"NewPass5678"} | G38: 204 | H38: ID=1のusers.password_hashが変更前と異なる値になる | I38: - | J38: AP-012、R-23 | K38: 自動 | L38: ap012_現在のパスワードが正しければ変更できる | M38: OK | N38: 46302 | O38: 佐々木（Claude Code） | P38: 自動テスト成功 | Q38: evidence/IT/IT_API結合_結果一覧_20261007.txt
A39: IT-AP012-N02 | B39: AP-012 パスワード変更 PUT /api/my/password | C39: 正常系 | D39: 変更後は新しいパスワードでログインできる | E39: 上記の変更を行った後 | F39: AP-010にgeneral@example.comとNewPass5678を送る | G39: 200 | H39: -（参照のみ） | I39: - | J39: R-23 | K39: 自動 | L39: ap012_変更後は新しいパスワードでログインできる | M39: OK | N39: 46302 | O39: 佐々木（Claude Code） | P39: 自動テスト成功 | Q39: evidence/IT/IT_API結合_結果一覧_20261007.txt
A40: IT-AP012-E01 | B40: AP-012 パスワード変更 PUT /api/my/password | C40: 異常系 | D40: 変更後は古いパスワードでログインできない | E40: パスワードをNewPass5678に変更した後 | F40: AP-010にgeneral@example.comとTest1234を送る | G40: 401「ログインできませんでした。入力内容をご確認のうえ、初めてご利用の場合は新規登録してください」（E-A-006） | H40: -（参照のみ） | I40: - | J40: R-23 | K40: 自動 | L40: ap012_変更後は古いパスワードでログインできない | M40: OK | N40: 46302 | O40: 佐々木（Claude Code） | P40: 自動テスト成功 | Q40: evidence/IT/IT_API結合_結果一覧_20261007.txt
...

Sheet IT_画面結合
A1: ID | B1: 対象 | C1: 区分 | D1: 確認する内容 | E1: 前提 | F1: 操作・入力 | G1: 期待結果 | H1: 期待結果（データベース） | I1: 確認SQL | J1: 根拠 | K1: 実施方法 | L1: 自動テスト | M1: 結果 | N1: 実施日 | O1: 実施者 | P1: 実際の結果・備考 | Q1: 証跡 | R1: 不具合Issue | S1: 再テスト結果 | T1: 再テスト日
A2: IT-NAV-N01 | B2: ログイン状態と画面遷移の制御 | C2: 正常系 | D2: 再読み込みしてもログイン状態が維持される | E2: 一般ユーザーでログイン | F2: SC-020でブラウザを再読み込みする | G2: SC-020が表示され、一般利用者向けのナビゲーションが表示されたままになる | H2: -（参照のみ） | I2: - | J2: 24_方式設計書 3.2 | K2: 手動 | M2: OK | N2: 46308 | O2: 佐々木 | Q2: 45_テストエビデンス_画面結合.xlsx／共通
A3: IT-NAV-N02 | B3: ログイン状態と画面遷移の制御 | C3: 正常系 | D3: ログアウトするとログイン画面に戻る | E3: 一般ユーザーでログイン | F3: 共通ナビゲーションの「ログアウト」を押す | G3: SC-010へ遷移する | H3: -（参照のみ） | I3: - | J3: 30_画面詳細設計書 3章 | K3: 手動 | M3: OK | N3: 46308 | O3: 佐々木 | Q3: 45_テストエビデンス_画面結合.xlsx／共通
A4: IT-NAV-N03 | B4: ログイン状態と画面遷移の制御 | C4: 正常系 | D4: 一般利用者のナビゲーションに「パスワード変更」がある | E4: 一般ユーザーでログイン | F4: 共通ナビゲーションを確認する | G4: 「イベント一覧／イベント検索／マイページ／パスワード変更／ログアウト」が表示される | H4: -（参照のみ） | I4: - | J4: 21_画面基本設計書 2章 | K4: 手動 | M4: OK | N4: 46308 | O4: 佐々木 | Q4: 45_テストエビデンス_画面結合.xlsx／共通
A5: IT-NAV-N04 | B5: ログイン状態と画面遷移の制御 | C5: 正常系 | D5: 管理者のナビゲーションに「パスワード変更」がある | E5: 管理者でログイン | F5: 共通ナビゲーションを確認する | G5: 「ダッシュボード／イベント管理／申込状況・実績／利用者管理／コメント管理／パスワード変更／ログアウト」が表示される | H5: -（参照のみ） | I5: - | J5: 21_画面基本設計書 2章 | K5: 手動 | M5: OK | N5: 46308 | O5: 佐々木 | Q5: 45_テストエビデンス_画面結合.xlsx／共通
A6: IT-NAV-E01 | B6: ログイン状態と画面遷移の制御 | C6: 異常系 | D6: ログアウト後は、ログインが必要な画面を開けない | E6: ログアウトした直後 | F6: URL/eventsを直接開く | G6: SC-010へ遷移する | H6: -（参照のみ） | I6: - | J6: 20_機能設計書 4.3 | K6: 手動 | M6: OK | N6: 46308 | O6: 佐々木 | Q6: 45_テストエビデンス_画面結合.xlsx／共通
A7: IT-NAV-E02 | B7: ログイン状態と画面遷移の制御 | C7: 異常系 | D7: 未ログインでは、ログインが必要な画面を開けない | E7: 未ログイン | F7: URL/my/applicationsを直接開く | G7: SC-010へ遷移する | H7: -（参照のみ） | I7: - | J7: 20_機能設計書 4.3 | K7: 手動 | M7: OK | N7: 46308 | O7: 佐々木 | Q7: 45_テストエビデンス_画面結合.xlsx／共通
A8: IT-NAV-E03 | B8: ログイン状態と画面遷移の制御 | C8: 異常系 | D8: 一般利用者は、管理者向けの画面を開けない | E8: 一般ユーザーでログイン | F8: URL/admin/dashboardを直接開く | G8: SC-020へ遷移する | H8: -（参照のみ） | I8: - | J8: 20_機能設計書 4.3 | K8: 手動 | M8: OK | N8: 46308 | O8: 佐々木 | Q8: 45_テストエビデンス_画面結合.xlsx／共通
A9: IT-NAV-E04 | B9: ログイン状態と画面遷移の制御 | C9: 異常系 | D9: ログイン状態が無効になると、操作時にログイン画面へ遷移する | E9: 一般ユーザーでログイン。その後、SQLでUPDATE users SET anonymized_at = NOW() WHERE id = 1を実行する | F9: 共通ナビゲーションの「マイページ」を押す | G9: SC-010へ遷移し、ナビゲーションが未ログインの表示になる | H9: -（参照のみ） | I9: - | J9: 24_方式設計書 5.3、33_共通詳細設計書 5.4 | K9: 手動 | M9: OK | N9: 46308 | O9: 佐々木 | Q9: 45_テストエビデンス_画面結合.xlsx／共通
A10: IT-SC010-N01 | B10: SC-010 ログイン・利用者登録 | C10: 正常系 | D10: 一般利用者でログインするとイベント一覧へ遷移する | E10: TD-00 | F10: メールアドレスgeneral@example.com、パスワードTest1234を入力し「ログイン」を押す | G10: SC-020へ遷移する | H10: -（参照のみ） | I10: - | J10: SC-010 イベント処理2 | K10: 手動 | M10: OK | N10: 46308 | O10: 佐々木 | Q10: 45_テストエビデンス_画面結合.xlsx／SC-010
A11: IT-SC010-N02 | B11: SC-010 ログイン・利用者登録 | C11: 正常系 | D11: 管理者でログインするとダッシュボードへ遷移する | E11: TD-00 | F11: メールアドレスadmin@example.com、パスワードTest1234を入力し「ログイン」を押す | G11: SC-110へ遷移する | H11: -（参照のみ） | I11: - | J11: SC-010 イベント処理2 | K11: 手動 | M11: OK | N11: 46308 | O11: 佐々木 | Q11: 45_テストエビデンス_画面結合.xlsx／SC-010
A12: IT-SC010-N03 | B12: SC-010 ログイン・利用者登録 | C12: 正常系 | D12: パスワード欄は入力した文字が伏せて表示される | E12: - | F12: ログインのパスワード欄にTest1234と入力する | G12: 入力した文字が「●」で表示される | H12: -（参照のみ） | I12: - | J12: SC-010 項目② | K12: 手動 | M12: OK | N12: 46308 | O12: 佐々木 | Q12: 45_テストエビデンス_画面結合.xlsx／SC-010
A13: IT-SC010-N04 | B13: SC-010 ログイン・利用者登録 | C13: 正常系 | D13: 新規登録すると、そのままログイン状態になる | E13: 未登録のメールアドレス | F13: 名前・メールアドレス・パスワードTest1234を入力し「登録してログイン」を押す | G13: SC-020へ遷移する | H13: usersに1行追加される（role_code=1、password_hashがハッシュ値） | I13: 【操作の前と後に実行し、期待結果のとおりであることを確認する】 SELECT id, name, email, role_code, password_hash, anonymized_at, updated_at FROM users ORDER BY id; | J13: SC-010 イベント処理3 | K13: 手動 | M13: OK | N13: 46308 | O13: 佐々木 | Q13: 45_テストエビデンス_画面結合.xlsx／SC-010
... A69: IT-SC022-E06 | B69: SC-022 イベント詳細・申込 | C69: 異常系 | D69: 存在しないイベントを開くとエラーが表示される | E69: 一般ユーザーでログイン | F69: URL/events/99999を直接開く | G69: 画面全体に「イベントが見つかりません」が表示される | H69: -（参照のみ） | I69: - | J69: SC-022 イベント処理1 | K69: 手動 | M69: OK | N69: 46308 | O69: 佐々木 | Q69: 45_テストエビデンス_画面結合.xlsx／SC-022
A70: IT-SC023-N01 | B70: SC-023 申込完了 | C70: 正常系 | D70: 受付済の申込結果が表示される | E70: 一般ユーザーでログイン、TD-02（申込なし） | F70: TD-02に申し込む | G70: ステータス「受付済」と申込日時が表示される。キャンセル待ちの補足説明は表示されない | H70: applications.status_code=1 | I70: 【操作の前と後に実行し、期待結果のとおりであることを確認する】 SELECT id, event_id, user_id, ticket_type_id, status_code, extra_answer, checked_in_at, updated_at FROM applications ORDER BY id; | J70: SC-023 項目①② | K70: 手動 | M70: OK | N70: 46308 | O70: 佐々木 | P70: 一般ユーザーはTD-02に申込済みのため、TD-05の利用者（一般ユーザー2）がTD-01に区分「学生」で申し込んで確認した（申込ID=4、受付済）。 | Q70: 45_テストエビデンス_画面結合.xlsx／SC-023
A71: IT-SC023-N02 | B71: SC-023 申込完了 | C71: 正常系 | D71: キャンセル待ちの申込結果と補足説明が表示される | E71: TD-02に他の利用者が受付済で申込済み。一般ユーザーでログイン | F71: TD-02に申し込む | G71: ステータス「キャンセル待ち」と、「満席のためキャンセル待ちとして登録されました。…」が表示される | H71: applications.status_code=2 | I71: 【操作の前と後に実行し、期待結果のとおりであることを確認する】 SELECT id, event_id, user_id, ticket_type_id, status_code, extra_answer, checked_in_at, updated_at FROM applications ORDER BY id; | J71: SC-023 項目③ | K71: 手動 | M71: OK | N71: 46308 | O71: 佐々木 | P71: 一般ユーザーがTD-02に受付済で申込済みのため、TD-05の利用者（一般ユーザー2）がTD-02に申し込んで確認した（申込ID=5、キャンセル待ち）。 | Q71: 45_テストエビデンス_画面結合.xlsx／SC-023
A72: IT-SC023-N03 | B72: SC-023 申込完了 | C72: 正常系 | D72: 申込直後に再読み込みしても、申込結果が表示される | E72: 申込直後のSC-023 | F72: ブラウザを再読み込みする | G72: 同じ申込結果が引き続き表示される | H72: -（参照のみ） | I72: - | J72: SC-023 イベント処理1 | K72: 手動 | M72: OK | N72: 46308 | O72: 佐々木 | Q72: 45_テストエビデンス_画面結合.xlsx／SC-023
A73: IT-SC023-N04 | B73: SC-023 申込完了 | C73: 正常系 | D73: 「イベント一覧へ」でイベント一覧に戻る | E73: 申込直後のSC-023 | F73: 「イベント一覧へ」を押す | G73: SC-020へ遷移する | H73: -（参照のみ） | I73: - | J73: SC-023 イベント処理2 | K73: 手動 | M73: OK | N73: 46308 | O73: 佐々木 | Q73: 45_テストエビデンス_画面結合.xlsx／SC-023
A74: IT-SC023-E01 | B74: SC-023 申込完了 | C74: 異常系 | D74: URLを直接指定すると申込結果を表示できない | E74: 一般ユーザーでログイン | F74: URL/events/{TD-02のID}/doneを直接開く | G74: 「申込結果を表示できません。イベント一覧からやり直してください。」が表示される | H74: -（参照のみ） | I74: - | J74: SC-023 項目⑤ | K74: 手動 | M74: OK | N74: 46308 | O74: 佐々木 | Q74: 45_テストエビデンス_画面結合.xlsx／SC-023
A75: IT-SC030-N01 | B75: SC-030 マイページ | C75: 正常系 | D75: 自分の申込が一覧表示される | E75: 一般ユーザーでログイン。受付済とキャンセル済の申込がある | F75: SC-030を開く | G75: イベント名・状況・開催日時・申込日時が表示される。キャンセル済の申込には「キャンセル」が表示されない | H75: -（参照のみ） | I75: - | J75: SC-030 項目④〜⑧ | K75: 手動 | M75: OK | N75: 46308 | O75: 佐々木 | Q75: 45_テストエビデンス_画面結合.xlsx／SC-030
A76: IT-SC030-N02 | B76: SC-030 マイページ | C76: 正常系 | D76: キャンセル待ちの申込には順位が表示される | E76: TD-05の利用者でログイン。TD-02にキャンセル待ち1番目の申込がある | F76: SC-030を開く | G76: 状況が「キャンセル待ち（1番目）」と表示される | H76: -（参照のみ） | I76: - | J76: SC-030 項目⑤ | K76: 手動 | M76: OK | N76: 46308 | O76: 佐々木 | Q76: 45_テストエビデンス_画面結合.xlsx／SC-030
A77: IT-SC030-N03 | B77: SC-030 マイページ | C77: 正常系 | D77: 申込をキャンセルできる | E77: 一般ユーザーでログイン。TD-02に受付済の申込がある | F77: その申込の「キャンセル」を押し、確認でOKを押す | G77: 状況が「キャンセル済」に変わり、「キャンセル」が消える | H77: 該当のapplications.status_codeが9になる | I77: 【操作の前と後に実行し、期待結果のとおりであることを確認する】 SELECT id, event_id, user_id, ticket_type_id, status_code, extra_answer, checked_in_at, updated_at FROM applications ORDER BY id; | J77: SC-030 イベント処理3 | K77: 手動 | M77: OK | N77: 46308 | O77: 佐々木 | Q77: 45_テストエビデンス_画面結合.xlsx／SC-030
A78: IT-SC030-N04 | B78: SC-030 マイページ | C78: 正常系 | D78: キャンセルの確認で取り消すと、キャンセルされない | E78: 一般ユーザーでログイン。TD-02に受付済の申込がある | F78: その申込の「キャンセル」を押し、確認で取り消す | G78: 状況は「受付済」のまま変わらない | H78: 該当のapplications.status_codeは1のまま | I78: 【操作の前と後に実行し、結果が同じことを確認する】 SELECT * FROM applications ORDER BY id; | J78: SC-030 イベント処理3 | K78: 手動 | M78: OK | N78: 46308 | O78: 佐々木 | Q78: 45_テストエビデンス_画面結合.xlsx／SC-030
A79: IT-SC030-N05 | B79: SC-030 マイページ | C79: 正常系 | D79: お気に入りタブに自分のお気に入りが表示される | E79: 一般ユーザーでログイン。TD-01をお気に入り登録済み | F79: 「お気に入り」タブを押す | G79: TD-01のイベント名・受付状況・開催日時・場所が表示される | H79: -（参照のみ） | I79: - | J79: SC-030 項目⑩〜⑬ | K79: 手動 | M79: OK | N79: 46308 | O79: 佐々木 | Q79: 45_テストエビデンス_画面結合.xlsx／SC-030
A80: IT-SC030-N06 | B80: SC-030 マイページ | C80: 正常系 | D80: お気に入りを解除できる | E80: 一般ユーザーでログイン。TD-01をお気に入り登録済み | F80: お気に入りタブで「お気に入り解除」を押す | G80: TD-01が一覧から消える。SC-020でもTD-01が「☆」になる | H80: favoritesの該当の行が削除される | I80: 【操作の前と後に実行し、期待結果のとおりであることを確認する】 SELECT id, event_id, user_id, created_at FROM favorites ORDER BY id; | J80: SC-030 イベント処理4 | K80: 手動 | M80: OK | N80: 46308 | O80: 佐々木 | Q80: 45_テストエビデンス_画面結合.xlsx／SC-030
A81: IT-SC030-N07 | B81: SC-030 マイページ | C81: 正常系 | D81: 退会するとログイン画面に戻る | E81: TD-05の利用者でログイン | F81: 「退会する」を押し、確認でOKを押す | G81: SC-010へ遷移する | H81: TD-05の利用者のusers.nameが「退会済み利用者」、password_hashがNULL、anonymized_atに日時が入る | I81: 【操作の前と後に実行し、期待結果のとおりであることを確認する】 SELECT id, name, email, role_code, password_hash, anonymized_at, updated_at FROM users ORDER BY id; | J81: SC-030 イベント処理5 | K81: 手動 | M81: OK | N81: 46309 | O81: 佐々木 | Q81: 45_テストエビデンス_画面結合.xlsx／SC-030
A82: IT-SC030-E01 | B82: SC-030 マイページ | C82: 異常系 | D82: 開催日時を過ぎた申込はキャンセルできない | E82: 一般ユーザーでログイン、TD-04 | F82: 「開催済テスト」の申込の「キャンセル」を押し、確認でOKを押す | G82: 「取消できません」が通知される | H82: 該当のapplications.status_codeは1のまま | I82: 【操作の前と後に実行し、結果が同じことを確認する】 SELECT * FROM applications ORDER BY id; | J82: E-B-010 | K82: 手動 | M82: OK | N82: 46308 | O82: 佐々木 | Q82: 45_テストエビデンス_画面結合.xlsx／SC-030
A83: IT-SC110-N01 | B83: SC-110 管理者ダッシュボード | C83: 正常系 | D83: 総イベント数がデータベースの件数と一致する | E83: 管理者でログイン | F83: SC-110を開く | G83: 総イベント数が、SELECT COUNT(*) FROM events WHERE deleted_at IS NULLの結果と一致する | H83: -（参照のみ） | I83: - | J83: SC-110 項目① | K83: 手動 | M83: OK | N83: 46308 | O83: 佐々木 | Q83: 45_テストエビデンス_画面結合.xlsx／SC-110
... A97: IT-SC121-N04 | B97: SC-121 イベント登録・編集 | C97: 正常系 | D97: 編集画面に既存の値が表示される | E97: 管理者でログイン、TD-02 | F97: SC-120でTD-02のイベント名を押す | G97: SC-121（編集）が開き、各入力欄にTD-02の値が表示される | H97: -（参照のみ） | I97: - | J97: SC-121 イベント処理2 | K97: 手動 | M97: OK | N97: 46309 | O97: 佐々木 | Q97: 45_テストエビデンス_画面結合.xlsx／SC-121
A98: IT-SC121-N05 | B98: SC-121 イベント登録・編集 | C98: 正常系 | D98: イベントを編集できる | E98: 管理者でログイン、TD-02 | F98: 場所を変更し「保存」を押す | G98: SC-120へ遷移し、変更後の場所が表示される | H98: TD-02のevents.placeが更新される | I98: 【操作の前と後に実行し、期待結果のとおりであることを確認する】 SELECT id, name, start_at, place, capacity, application_deadline, deleted_at, updated_at FROM events ORDER BY id; | J98: SC-121 イベント処理5 | K98: 手動 | M98: NG | N98: 46309 | O98: 佐々木 | P98: 「区分に申込があるため変更できません」と表示され、保存できなかった。events の ID=53 の place は「会議室A」のまま変わっていない。参加区分は変更していない（区分の無いイベント）。 【再テスト 2026/10/14】Issue #19 の修正後、場所を「会議室C」に変えて保存するとSC-120へ遷移し、変更後の場所が表示された。events の ID=53 の place が「会議室C」に更新され、ticket_types は変わっていない。 | Q98: 45_テストエビデンス_画面結合.xlsx／SC-121 | R98: #19 | S98: OK | T98: 46309
A99: IT-SC121-N06 | B99: SC-121 イベント登録・編集 | C99: 正常系 | D99: 複製では、開催日時と申込締切が空で、案内が表示される | E99: 管理者でログイン、TD-01 | F99: SC-120でTD-01の「複製」を押す | G99: 開催日時・申込締切が空で、「「（イベント名）」の内容を複写しました。…」の案内が表示される | H99: -（参照のみ） | I99: - | J99: SC-121 項目③ | K99: 手動 | M99: OK | N99: 46308 | O99: 佐々木 | P99: IT-SC120-N03と同じ画面で確認した。 | Q99: 45_テストエビデンス_画面結合.xlsx／SC-121
A100: IT-SC121-E01 | B100: SC-121 イベント登録・編集 | C100: 異常系 | D100: イベント名が未入力だと、APIを呼ばずにエラーを表示する | E100: 管理者でログイン | F100: イベント名を空のまま「保存」を押す | G100: イベント名の下に「イベント名を入力してください」が表示される。Networkタブに/api/eventsへの送信が出ない | H100: eventsは変更されない | I100: 【操作の前と後に実行し、結果が同じことを確認する】 SELECT * FROM events ORDER BY id; | J100: SC-121 イベント処理5 | K100: 手動 | M100: OK | N100: 46309 | O100: 佐々木 | Q100: 45_テストエビデンス_画面結合.xlsx／SC-121
A101: IT-SC121-E02 | B101: SC-121 イベント登録・編集 | C101: 異常系 | D101: 開催日時が過去だとエラーになる | E101: 管理者でログイン | F101: 開催日時に過去の日時を入力し「保存」を押す | G101: 開催日時の下に「未来の日時を入力してください」が表示される | H101: eventsは変更されない | I101: 【操作の前と後に実行し、結果が同じことを確認する】 SELECT * FROM events ORDER BY id; | J101: E-V-011 | K101: 手動 | M101: OK | N101: 46309 | O101: 佐々木 | Q101: 45_テストエビデンス_画面結合.xlsx／SC-121
A102: IT-SC121-E03 | B102: SC-121 イベント登録・編集 | C102: 異常系 | D102: 申込締切が開催日時より後だとエラーになる | E102: 管理者でログイン | F102: 申込締切に開催日時より後の日時を入力し「保存」を押す | G102: 「申込締切は開催日時より前にしてください」が表示される | H102: eventsは変更されない | I102: 【操作の前と後に実行し、結果が同じことを確認する】 SELECT * FROM events ORDER BY id; | J102: E-V-021 | K102: 手動 | M102: OK | N102: 46309 | O102: 佐々木 | Q102: 45_テストエビデンス_画面結合.xlsx／SC-121
A103: IT-SC121-E04 | B103: SC-121 イベント登録・編集 | C103: 異常系 | D103: 申込のある参加区分は変更できない | E103: 管理者でログイン。TD-01の区分「一般」に受付済の申込がある | F103: TD-01の編集で区分名を変更し「保存」を押す | G103: 「区分に申込があるため変更できません」が表示される | H103: ticket_typesは変更されない | I103: 【操作の前と後に実行し、結果が同じことを確認する】 SELECT * FROM ticket_types ORDER BY event_id, id; | J103: E-B-007 | K103: 手動 | M103: OK | N103: 46309 | O103: 佐々木 | Q103: 45_テストエビデンス_画面結合.xlsx／SC-121
A104: IT-SC122-N01 | B104: SC-122 削除済みイベント | C104: 正常系 | D104: 削除済みのイベントが一覧表示される | E104: 管理者でログイン。削除済みのイベントがある | F104: SC-122を開く | G104: イベント名・開催日時・場所・定員・削除日時と、「復元」「複製」が表示される | H104: -（参照のみ） | I104: - | J104: SC-122 項目②〜⑧ | K104: 手動 | M104: OK | N104: 46309 | O104: 佐々木 | Q104: 45_テストエビデンス_画面結合.xlsx／SC-122
A105: IT-SC122-N02 | B105: SC-122 削除済みイベント | C105: 正常系 | D105: 削除済みのイベントを復元できる | E105: 管理者でログイン。削除済みのイベントがある | F105: 「復元」を押し、確認でOKを押す | G105: そのイベントがSC-122の一覧から消え、SC-120の一覧に表示される | H105: 対象のevents.deleted_atがNULLになる | I105: 【操作の前と後に実行し、期待結果のとおりであることを確認する】 SELECT id, name, start_at, place, capacity, application_deadline, deleted_at, updated_at FROM events ORDER BY id; | J105: SC-122 イベント処理2 | K105: 手動 | M105: OK | N105: 46309 | O105: 佐々木 | Q105: 45_テストエビデンス_画面結合.xlsx／SC-122
A106: IT-SC122-N03 | B106: SC-122 削除済みイベント | C106: 正常系 | D106: 削除済みのイベントを複製できる | E106: 管理者でログイン。削除済みのイベントがある | F106: 「複製」を押す | G106: SC-121（新規登録）へ遷移し、開催日時・申込締切以外の項目に内容が入力されている | H106: eventsは変更されない | I106: 【操作の前と後に実行し、結果が同じことを確認する】 SELECT * FROM events ORDER BY id; | J106: SC-122 イベント処理3 | K106: 手動 | M106: OK | N106: 46309 | O106: 佐々木 | Q106: 45_テストエビデンス_画面結合.xlsx／SC-122
A107: IT-SC123-N01 | B107: SC-123 当日受付 | C107: 正常系 | D107: 申込者とアンケート回答が表示される | E107: 管理者でログイン。TD-01にアンケート回答付きの申込がある | F107: TD-01のSC-123を開く | G107: アンケートの質問文と、申込者・区分・ステータス・チェックイン（「未チェックイン」）・アンケート回答が表示される | H107: -（参照のみ） | I107: - | J107: SC-123 項目②〜⑦ | K107: 手動 | M107: OK | N107: 46309 | O107: 佐々木 | Q107: 45_テストエビデンス_画面結合.xlsx／SC-123
A108: IT-SC123-N02 | B108: SC-123 当日受付 | C108: 正常系 | D108: 参加区分の無いイベントは区分が「-」で表示される | E108: 管理者でログイン。TD-02に申込がある | F108: TD-02のSC-123を開く | G108: 区分の列が「-」と表示される | H108: -（参照のみ） | I108: - | J108: SC-123 項目④ | K108: 手動 | M108: OK | N108: 46309 | O108: 佐々木 | Q108: 45_テストエビデンス_画面結合.xlsx／SC-123
...

Sheet ST
A1: ID | B1: 対象 | C1: 区分 | D1: 確認する内容 | E1: 前提 | F1: 操作・入力 | G1: 期待結果 | H1: 期待結果（データベース） | I1: 確認SQL | J1: 根拠 | K1: 実施方法 | L1: 自動テスト | M1: 結果 | N1: 実施日 | O1: 実施者 | P1: 実際の結果・備考 | Q1: 証跡 | R1: 不具合Issue | S1: 再テスト結果 | T1: 再テスト日
A2: ST-01-01 | B2: ST-01 一般利用者がイベントを探し、申し込み、参加をやめる | C2: 正常系 | D2: ST-01 一般利用者がイベントを探し、申し込み、参加をやめる | E2: 前のステップの結果 | F2: 【一般C】SC-010で名前「ST利用者」、メールアドレスst-user@example.com、パスワードTest1234を入力し「登録してログイン」を押す | G2: SC-020へ遷移する | H2: usersにst-user@example.comの行が追加される（role_code=1） | I2: 【操作の前と後に実行し、期待結果のとおりであることを確認する】 SELECT id, name, email, role_code, password_hash, anonymized_at, updated_at FROM users ORDER BY id; | J2: 10_要件定義書 4章・7章 | K2: 手動 | M2: OK | N2: 46309 | O2: 佐々木 | P2: 入力画面の撮影は漏れたため、登録直後（14:52）のイベント一覧の画面とデータベースの前後で確認した（users に ID=5「ST利用者」、role_code=1 が 14:51:44 に追加）。 | Q2: 45_テストエビデンス_総合.xlsx／ST-01
A3: ST-01-02 | B3: ST-01 一般利用者がイベントを探し、申し込み、参加をやめる | C3: 正常系 | D3: ST-01 一般利用者がイベントを探し、申し込み、参加をやめる | E3: 前のステップの結果 | F3: 【一般C】SC-020をカレンダー表示に切り替え、TD-01の開催月を表示する | G3: TD-01の開催日のマスに「区分テスト」が表示される | H3: -（参照のみ） | I3: - | J3: 10_要件定義書 4章・7章 | K3: 手動 | M3: OK | N3: 46309 | O3: 佐々木 | Q3: 45_テストエビデンス_総合.xlsx／ST-01
A4: ST-01-03 | B4: ST-01 一般利用者がイベントを探し、申し込み、参加をやめる | C4: 正常系 | D4: ST-01 一般利用者がイベントを探し、申し込み、参加をやめる | E4: 前のステップの結果 | F4: 【一般C】SC-021でキーワードに「区分テスト」と入力する | G4: 「区分テスト」だけが表示される | H4: -（参照のみ） | I4: - | J4: 10_要件定義書 4章・7章 | K4: 手動 | M4: OK | N4: 46309 | O4: 佐々木 | Q4: 45_テストエビデンス_総合.xlsx／ST-01
A5: ST-01-04 | B5: ST-01 一般利用者がイベントを探し、申し込み、参加をやめる | C5: 正常系 | D5: ST-01 一般利用者がイベントを探し、申し込み、参加をやめる | E5: 前のステップの結果 | F5: 【一般C】「区分テスト」を押してSC-022を開き、「☆ お気に入りに追加」を押す | G5: 「★ お気に入り済み」に変わり、お気に入り数が1になる | H5: favoritesに、一般CとTD-01の行が追加される | I5: 【操作の前と後に実行し、期待結果のとおりであることを確認する】 SELECT id, event_id, user_id, created_at FROM favorites ORDER BY id; | J5: 10_要件定義書 4章・7章 | K5: 手動 | M5: OK | N5: 46309 | O5: 佐々木 | Q5: 45_テストエビデンス_総合.xlsx／ST-01
A6: ST-01-05 | B6: ST-01 一般利用者がイベントを探し、申し込み、参加をやめる | C6: 正常系 | D6: ST-01 一般利用者がイベントを探し、申し込み、参加をやめる | E6: 前のステップの結果 | F6: 【一般C】参加区分「一般」を選び、アンケートに「勉強のため」と入力して「申し込む」を押す | G6: SC-023にステータス「受付済」が表示される | H6: applicationsに、一般CとTD-01の行が追加される（status_code=1、ticket_type_id=「一般」、extra_answer=「勉強のため」） | I6: 【操作の前と後に実行し、期待結果のとおりであることを確認する】 SELECT id, event_id, user_id, ticket_type_id, status_code, extra_answer, checked_in_at, updated_at FROM applications ORDER BY id; | J6: 10_要件定義書 4章・7章 | K6: 手動 | M6: OK | N6: 46309 | O6: 佐々木 | Q6: 45_テストエビデンス_総合.xlsx／ST-01
A7: ST-01-06 | B7: ST-01 一般利用者がイベントを探し、申し込み、参加をやめる | C7: 正常系 | D7: ST-01 一般利用者がイベントを探し、申し込み、参加をやめる | E7: 前のステップの結果 | F7: 【一般C】「イベント一覧へ」を押し、TD-01のSC-022を開く | G7: 参加区分「一般」の残り枠が0と表示される | H7: -（参照のみ） | I7: - | J7: 10_要件定義書 4章・7章 | K7: 手動 | M7: OK | N7: 46309 | O7: 佐々木 | Q7: 45_テストエビデンス_総合.xlsx／ST-01
A8: ST-01-07 | B8: ST-01 一般利用者がイベントを探し、申し込み、参加をやめる | C8: 正常系 | D8: ST-01 一般利用者がイベントを探し、申し込み、参加をやめる | E8: 前のステップの結果 | F8: 【一般C】コメント欄に「駐車場はありますか」と入力し「投稿」を押す | G8: コメント一覧に追加される | H8: event_commentsに、一般CとTD-01の行が追加される | I8: 【操作の前と後に実行し、期待結果のとおりであることを確認する】 SELECT id, event_id, user_id, parent_comment_id, body, deleted_at, updated_at FROM event_comments ORDER BY id; | J8: 10_要件定義書 4章・7章 | K8: 手動 | M8: OK | N8: 46309 | O8: 佐々木 | Q8: 45_テストエビデンス_総合.xlsx／ST-01
A9: ST-01-08 | B9: ST-01 一般利用者がイベントを探し、申し込み、参加をやめる | C9: 正常系 | D9: ST-01 一般利用者がイベントを探し、申し込み、参加をやめる | E9: 前のステップの結果 | F9: 【一般C】SC-030の申込一覧タブを開く | G9: 「区分テスト」が状況「受付済」で表示される | H9: -（参照のみ） | I9: - | J9: 10_要件定義書 4章・7章 | K9: 手動 | M9: OK | N9: 46309 | O9: 佐々木 | Q9: 45_テストエビデンス_総合.xlsx／ST-01
A10: ST-01-09 | B10: ST-01 一般利用者がイベントを探し、申し込み、参加をやめる | C10: 正常系 | D10: ST-01 一般利用者がイベントを探し、申し込み、参加をやめる | E10: 前のステップの結果 | F10: 【一般C】SC-030のお気に入りタブを開く | G10: 「区分テスト」が表示される | H10: -（参照のみ） | I10: - | J10: 10_要件定義書 4章・7章 | K10: 手動 | M10: OK | N10: 46309 | O10: 佐々木 | Q10: 45_テストエビデンス_総合.xlsx／ST-01
A11: ST-01-10 | B11: ST-01 一般利用者がイベントを探し、申し込み、参加をやめる | C11: 正常系 | D11: ST-01 一般利用者がイベントを探し、申し込み、参加をやめる | E11: 前のステップの結果 | F11: 【一般C】申込一覧タブで「区分テスト」の「キャンセル」を押し、確認でOKを押す | G11: 状況が「キャンセル済」に変わる | H11: ST-01-05で追加された行のstatus_codeが9になる（行は残る） | I11: 【操作の前と後に実行し、期待結果のとおりであることを確認する】 SELECT id, event_id, user_id, ticket_type_id, status_code, extra_answer, checked_in_at, updated_at FROM applications ORDER BY id; | J11: 10_要件定義書 4章・7章 | K11: 手動 | M11: OK | N11: 46309 | O11: 佐々木 | Q11: 45_テストエビデンス_総合.xlsx／ST-01
A12: ST-01-11 | B12: ST-01 一般利用者がイベントを探し、申し込み、参加をやめる | C12: 正常系 | D12: ST-01 一般利用者がイベントを探し、申し込み、参加をやめる | E12: 前のステップの結果 | F12: 【一般C】TD-01のSC-022を開き、参加区分「学生」を選んで「申し込む」を押す | G12: SC-023にステータス「受付済」が表示される | H12: applicationsに新しい行が追加される（status_code=1、ticket_type_id=「学生」）。キャンセル済の行は残る | I12: 【操作の前と後に実行し、期待結果のとおりであることを確認する】 SELECT id, event_id, user_id, ticket_type_id, status_code, extra_answer, checked_in_at, updated_at FROM applications ORDER BY id; | J12: 10_要件定義書 4章・7章 | K12: 手動 | M12: OK | N12: 46309 | O12: 佐々木 | Q12: 45_テストエビデンス_総合.xlsx／ST-01
A13: ST-01-12 | B13: ST-01 一般利用者がイベントを探し、申し込み、参加をやめる | C13: 正常系 | D13: ST-01 一般利用者がイベントを探し、申し込み、参加をやめる | E13: 前のステップの結果 | F13: 【一般C】SC-030の申込一覧タブを開く | G13: 「区分テスト」が、「受付済」と「キャンセル済」の2件表示される | H13: applicationsの一般CとTD-01の行が2件（status_codeが1と9） | I13: 【操作の前と後に実行し、期待結果のとおりであることを確認する】 SELECT id, event_id, user_id, ticket_type_id, status_code, extra_answer, checked_in_at, updated_at FROM applications ORDER BY id; | J13: 10_要件定義書 4章・7章 | K13: 手動 | M13: OK | N13: 46309 | O13: 佐々木 | Q13: 45_テストエビデンス_総合.xlsx／ST-01
A14: ST-02-01 | B14: ST-02 管理者がイベントを準備し、当日受付と実績確認を行う | C14: 正常系 | D14: ST-02 管理者がイベントを準備し、当日受付と実績確認を行う | E14: 前のステップの結果 | F14: 【管理者】SC-010でadmin@example.comとTest1234を入力し「ログイン」を押す | G14: SC-110へ遷移し、5つの指標が表示される | H14: -（参照のみ） | I14: - | J14: 10_要件定義書 4章・7章 | K14: 手動 | M14: OK | N14: 46309 | O14: 佐々木 | Q14: 45_テストエビデンス_総合.xlsx／ST-02
... A21: ST-02-08 | B21: ST-02 管理者がイベントを準備し、当日受付と実績確認を行う | C21: 正常系 | D21: ST-02 管理者がイベントを準備し、当日受付と実績確認を行う | E21: 前のステップの結果 | F21: 【管理者】一般Aの行の「チェックイン」を押す | G21: チェックインの列に日時が表示される | H21: 一般Aの申込のapplications.checked_in_atに日時が入る | I21: 【操作の前と後に実行し、期待結果のとおりであることを確認する】 SELECT id, event_id, user_id, ticket_type_id, status_code, extra_answer, checked_in_at, updated_at FROM applications ORDER BY id; | J21: 10_要件定義書 4章・7章 | K21: 手動 | M21: OK | N21: 46309 | O21: 佐々木 | Q21: 45_テストエビデンス_総合.xlsx／ST-02
A22: ST-02-09 | B22: ST-02 管理者がイベントを準備し、当日受付と実績確認を行う | C22: 正常系 | D22: ST-02 管理者がイベントを準備し、当日受付と実績確認を行う | E22: 前のステップの結果 | F22: 【管理者】SC-130を開く | G22: 「ST説明会」の行に、定員3・受付済数1・充足率33%が表示される | H22: -（参照のみ） | I22: - | J22: 10_要件定義書 4章・7章 | K22: 手動 | M22: OK | N22: 46309 | O22: 佐々木 | P22: 「ST説明会」の行に定員3・受付済数1・充足率33%が表示された。 | Q22: 45_テストエビデンス_総合.xlsx／ST-02
A23: ST-02-10 | B23: ST-02 管理者がイベントを準備し、当日受付と実績確認を行う | C23: 正常系 | D23: ST-02 管理者がイベントを準備し、当日受付と実績確認を行う | E23: 前のステップの結果 | F23: 【管理者】「CSVダウンロード」を押し、ダウンロードしたファイルを開く | G23: 「ST説明会」の行に、申込者名「一般ユーザー」、ステータス「受付済」、アンケート回答「資料はもらえますか」、参加区分「午前」が出力されている | H23: -（参照のみ） | I23: - | J23: 10_要件定義書 4章・7章 | K23: 手動 | M23: OK | N23: 46309 | O23: 佐々木 | Q23: 45_テストエビデンス_総合.xlsx／ST-02
A24: ST-02-11 | B24: ST-02 管理者がイベントを準備し、当日受付と実績確認を行う | C24: 正常系 | D24: ST-02 管理者がイベントを準備し、当日受付と実績確認を行う | E24: 前のステップの結果 | F24: 【管理者】SC-120で「ST説明会」の「複製」を押す | G24: SC-121（新規登録）に、開催日時・申込締切以外の項目が入力された状態で表示される | H24: eventsは変更されない | I24: 【操作の前と後に実行し、結果が同じことを確認する】 SELECT * FROM events ORDER BY id; | J24: 10_要件定義書 4章・7章 | K24: 手動 | M24: OK | N24: 46309 | O24: 佐々木 | P24: 開催日時・申込締切以外の項目が複写された。参加区分は「午後」「午前」の順で表示され、複製元の登録順（午前・午後）と異なる（設計書に並び順の定めは無い）。 | Q24: 45_テストエビデンス_総合.xlsx／ST-02
A25: ST-02-12 | B25: ST-02 管理者がイベントを準備し、当日受付と実績確認を行う | C25: 正常系 | D25: ST-02 管理者がイベントを準備し、当日受付と実績確認を行う | E25: 前のステップの結果 | F25: 【管理者】開催日時・申込締切を入力し、イベント名を「ST説明会（第2回）」に変えて「保存」を押す | G25: SC-120に「ST説明会（第2回）」が申込状況「0 / 3」で表示される | H25: eventsに1行追加される。複製元の申込（applications）は新しいイベントに引き継がれていない | I25: 【操作の前と後に実行し、期待結果のとおりであることを確認する】 SELECT id, name, start_at, place, capacity, application_deadline, deleted_at, updated_at FROM events ORDER BY id; SELECT id, event_id, user_id, ticket_type_id, status_code, extra_answer, checked_in_at, updated_at FROM applications ORDER BY id; | J25: 10_要件定義書 4章・7章 | K25: 手動 | M25: OK | N25: 46309 | O25: 佐々木 | Q25: 45_テストエビデンス_総合.xlsx／ST-02
A26: ST-02-13 | B26: ST-02 管理者がイベントを準備し、当日受付と実績確認を行う | C26: 正常系 | D26: ST-02 管理者がイベントを準備し、当日受付と実績確認を行う | E26: 前のステップの結果 | F26: 【管理者】SC-150を開く | G26: ST-01で投稿されたコメントがある場合を含め、全イベントのコメントが新しい順に表示される | H26: -（参照のみ） | I26: - | J26: 10_要件定義書 4章・7章 | K26: 手動 | M26: OK | N26: 46309 | O26: 佐々木 | P26: シナリオ開始時にデータを作り直したため、コメントは0件（「コメントはありません。」）の表示を確認した。 | Q26: 45_テストエビデンス_総合.xlsx／ST-02
A27: ST-03-01 | B27: ST-03 定員に達したイベントで、キャンセル待ちが繰り上がる | C27: 正常系 | D27: ST-03 定員に達したイベントで、キャンセル待ちが繰り上がる | E27: 前のステップの結果 | F27: 【一般A】TD-02（定員1）のSC-022で「申し込む」を押す | G27: SC-023にステータス「受付済」が表示される | H27: TD-02のapplicationsに一般Aの行（status_code=1）が追加される | I27: 【操作の前と後に実行し、期待結果のとおりであることを確認する】 SELECT id, event_id, user_id, ticket_type_id, status_code, extra_answer, checked_in_at, updated_at FROM applications ORDER BY id; | J27: 10_要件定義書 4章・7章 | K27: 手動 | M27: OK | N27: 46309 | O27: 佐々木 | Q27: 45_テストエビデンス_総合.xlsx／ST-03
A28: ST-03-02 | B28: ST-03 定員に達したイベントで、キャンセル待ちが繰り上がる | C28: 正常系 | D28: ST-03 定員に達したイベントで、キャンセル待ちが繰り上がる | E28: 前のステップの結果 | F28: 【一般B】TD-02のSC-022を開く | G28: 残り枠が0で、ボタンが「キャンセル待ちで申し込む」と表示される | H28: -（参照のみ） | I28: - | J28: 10_要件定義書 4章・7章 | K28: 手動 | M28: OK | N28: 46309 | O28: 佐々木 | P28: SC-022 ではなく、SC-020（イベント一覧）の詳細の展開で確認した。残り枠0名、「満席のため、申し込むとキャンセル待ちに登録されます。」と「キャンセル待ちで申し込む」ボタンが表示された。 | Q28: 45_テストエビデンス_総合.xlsx／ST-03
A29: ST-03-03 | B29: ST-03 定員に達したイベントで、キャンセル待ちが繰り上がる | C29: 正常系 | D29: ST-03 定員に達したイベントで、キャンセル待ちが繰り上がる | E29: 前のステップの結果 | F29: 【一般B】「キャンセル待ちで申し込む」を押す | G29: SC-023にステータス「キャンセル待ち」と補足説明が表示される | H29: 一般Bの行（status_code=2）が追加される | I29: 【操作の前と後に実行し、期待結果のとおりであることを確認する】 SELECT id, event_id, user_id, ticket_type_id, status_code, extra_answer, checked_in_at, updated_at FROM applications ORDER BY id; | J29: 10_要件定義書 4章・7章 | K29: 手動 | M29: OK | N29: 46309 | O29: 佐々木 | Q29: 45_テストエビデンス_総合.xlsx／ST-03
A30: ST-03-04 | B30: ST-03 定員に達したイベントで、キャンセル待ちが繰り上がる | C30: 正常系 | D30: ST-03 定員に達したイベントで、キャンセル待ちが繰り上がる | E30: 前のステップの結果 | F30: 【一般C】SC-010で新規登録（st-wait@example.com）し、TD-02のSC-022で「キャンセル待ちで申し込む」を押す | G30: SC-023にステータス「キャンセル待ち」が表示される | H30: 一般Cの行（status_code=2）が追加される | I30: 【操作の前と後に実行し、期待結果のとおりであることを確認する】 SELECT id, event_id, user_id, ticket_type_id, status_code, extra_answer, checked_in_at, updated_at FROM applications ORDER BY id; | J30: 10_要件定義書 4章・7章 | K30: 手動 | M30: OK | N30: 46309 | O30: 佐々木 | Q30: 45_テストエビデンス_総合.xlsx／ST-03
A31: ST-03-05 | B31: ST-03 定員に達したイベントで、キャンセル待ちが繰り上がる | C31: 正常系 | D31: ST-03 定員に達したイベントで、キャンセル待ちが繰り上がる | E31: 前のステップの結果 | F31: 【一般B】SC-030の申込一覧タブを開く | G31: TD-02が「キャンセル待ち（1番目）」と表示される | H31: -（参照のみ） | I31: - | J31: 10_要件定義書 4章・7章 | K31: 手動 | M31: OK | N31: 46309 | O31: 佐々木 | Q31: 45_テストエビデンス_総合.xlsx／ST-03
A32: ST-03-06 | B32: ST-03 定員に達したイベントで、キャンセル待ちが繰り上がる | C32: 正常系 | D32: ST-03 定員に達したイベントで、キャンセル待ちが繰り上がる | E32: 前のステップの結果 | F32: 【一般C】SC-030の申込一覧タブを開く | G32: TD-02が「キャンセル待ち（2番目）」と表示される | H32: -（参照のみ） | I32: - | J32: 10_要件定義書 4章・7章 | K32: 手動 | M32: OK | N32: 46309 | O32: 佐々木 | Q32: 45_テストエビデンス_総合.xlsx／ST-03
A33: ST-03-07 | B33: ST-03 定員に達したイベントで、キャンセル待ちが繰り上がる | C33: 正常系 | D33: ST-03 定員に達したイベントで、キャンセル待ちが繰り上がる | E33: 前のステップの結果 | F33: 【一般A】SC-030でTD-02の「キャンセル」を押し、確認でOKを押す | G33: 状況が「キャンセル済」に変わる | H33: 一般Aの行のstatus_code=9、一般Bの行のstatus_code=1、一般Cの行のstatus_code=2 | I33: 【操作の前と後に実行し、期待結果のとおりであることを確認する】 SELECT id, event_id, user_id, ticket_type_id, status_code, extra_answer, checked_in_at, updated_at FROM applications ORDER BY id; | J33: 10_要件定義書 4章・7章 | K33: 手動 | M33: OK | N33: 46309 | O33: 佐々木 | Q33: 45_テストエビデンス_総合.xlsx／ST-03
A34: ST-03-08 | B34: ST-03 定員に達したイベントで、キャンセル待ちが繰り上がる | C34: 正常系 | D34: ST-03 定員に達したイベントで、キャンセル待ちが繰り上がる | E34: 前のステップの結果 | F34: 【一般B】SC-030の申込一覧タブを開き直す | G34: TD-02が「受付済」と表示され、順位は表示されない | H34: -（参照のみ） | I34: - | J34: 10_要件定義書 4章・7章 | K34: 手動 | M34: OK | N34: 46309 | O34: 佐々木 | Q34: 45_テストエビデンス_総合.xlsx／ST-03
A35: ST-03-09 | B35: ST-03 定員に達したイベントで、キャンセル待ちが繰り上がる | C35: 正常系 | D35: ST-03 定員に達したイベントで、キャンセル待ちが繰り上がる | E35: 前のステップの結果 | F35: 【一般C】SC-030の申込一覧タブを開き直す | G35: TD-02が「キャンセル待ち（1番目）」と表示される（順位が繰り上がる） | H35: -（参照のみ） | I35: - | J35: 10_要件定義書 4章・7章 | K35: 手動 | M35: OK | N35: 46309 | O35: 佐々木 | Q35: 45_テストエビデンス_総合.xlsx／ST-03
A36: ST-03-10 | B36: ST-03 定員に達したイベントで、キャンセル待ちが繰り上がる | C36: 正常系 | D36: ST-03 定員に達したイベントで、キャンセル待ちが繰り上がる | E36: 前のステップの結果 | F36: 【管理者】TD-02のSC-123を開く | G36: 一般Aが「キャンセル済」、一般Bが「受付済」、一般Cが「キャンセル待ち」で表示される | H36: -（参照のみ） | I36: - | J36: 10_要件定義書 4章・7章 | K36: 手動 | M36: OK | N36: 46309 | O36: 佐々木 | Q36: 45_テストエビデンス_総合.xlsx／ST-03
A37: ST-03-11 | B37: ST-03 定員に達したイベントで、キャンセル待ちが繰り上がる | C37: 正常系 | D37: ST-03 定員に達したイベントで、キャンセル待ちが繰り上がる | E37: 前のステップの結果 | F37: 【管理者】SC-130を開く | G37: TD-02の受付済数が1（定員1を超えていない）と表示される | H37: TD-02のapplicationsのうちstatus_code=1の行が1件 | I37: 【操作の前と後に実行し、期待結果のとおりであることを確認する】 SELECT id, event_id, user_id, ticket_type_id, status_code, extra_answer, checked_in_at, updated_at FROM applications ORDER BY id; | J37: 10_要件定義書 4章・7章 | K37: 手動 | M37: OK | N37: 46309 | O37: 佐々木 | Q37: 45_テストエビデンス_総合.xlsx／ST-03
A38: ST-04-01 | B38: ST-04 利用者のアカウントを管理する（管理者の登録・降格、退会） | C38: 正常系 | D38: ST-04 利用者のアカウントを管理する（管理者の登録・降格、退会） | E38: 前のステップの結果 | F38: 【管理者】SC-140で、名前「ST管理者」、メールアドレスst-admin@example.com、初期パスワードTest1234を入力し「管理者を登録」を押す | G38: 一覧に「ST管理者」がロール「管理者」で追加される | H38: usersにst-admin@example.comの行が追加される（role_code=2） | I38: 【操作の前と後に実行し、期待結果のとおりであることを確認する】 SELECT id, name, email, role_code, password_hash, anonymized_at, updated_at FROM users ORDER BY id; | J38: 10_要件定義書 4章・7章 | K38: 手動 | M38: OK | N38: 46309 | O38: 佐々木 | Q38: 45_テストエビデンス_総合.xlsx／ST-04
A39: ST-04-02 | B39: ST-04 利用者のアカウントを管理する（管理者の登録・降格、退会） | C39: 正常系 | D39: ST-04 利用者のアカウントを管理する（管理者の登録・降格、退会） | E39: 前のステップの結果 | F39: 【ST管理者】別のブラウザのSC-010で、st-admin@example.comとTest1234を入力し「ログイン」を押す | G39: SC-110へ遷移する（登録された管理者アカウントで管理者として利用できる） | H39: -（参照のみ） | I39: - | J39: 10_要件定義書 4章・7章 | K39: 手動 | M39: OK | N39: 46309 | O39: 佐々木 | Q39: 45_テストエビデンス_総合.xlsx／ST-04
A40: ST-04-03 | B40: ST-04 利用者のアカウントを管理する（管理者の登録・降格、退会） | C40: 正常系 | D40: ST-04 利用者のアカウントを管理する（管理者の登録・降格、退会） | E40: 前のステップの結果 | F40: 【管理者】SC-140で「ST管理者」の名前を押し、SC-141で「管理者権限を外す」を押して確認でOKを押す | G40: 利用者区分が「一般利用者」に変わる | H40: 「ST管理者」のusers.role_codeが1になる | I40: 【操作の前と後に実行し、期待結果のとおりであることを確認する】 SELECT id, name, email, role_code, password_hash, anonymized_at, updated_at FROM users ORDER BY id; | J40: 10_要件定義書 4章・7章 | K40: 手動 | M40: OK | N40: 46309 | O40: 佐々木 | Q40: 45_テストエビデンス_総合.xlsx／ST-04
... A46: ST-04-09 | B46: ST-04 利用者のアカウントを管理する（管理者の登録・降格、退会） | C46: 正常系 | D46: ST-04 利用者のアカウントを管理する（管理者の登録・降格、退会） | E46: 前のステップの結果 | F46: 【管理者】SC-140を開く | G46: ID=1の行の名前が「退会済み利用者」になり、「退会済み」が表示される | H46: -（参照のみ） | I46: - | J46: 10_要件定義書 4章・7章 | K46: 手動 | M46: OK | N46: 46309 | O46: 佐々木 | Q46: 45_テストエビデンス_総合.xlsx／ST-04
A47: ST-04-10 | B47: ST-04 利用者のアカウントを管理する（管理者の登録・降格、退会） | C47: 正常系 | D47: ST-04 利用者のアカウントを管理する（管理者の登録・降格、退会） | E47: 前のステップの結果 | F47: 【管理者】ID=1の名前を押してSC-141を開く | G47: 申込一覧・お気に入り一覧・コメント履歴に、ST-04-05〜07の内容が残っている | H47: ST-04-05〜07で追加されたapplications・event_comments・favoritesの行が残っている | I47: 【操作の前と後に実行し、期待結果のとおりであることを確認する】 SELECT id, event_id, user_id, ticket_type_id, status_code, extra_answer, checked_in_at, updated_at FROM applications ORDER BY id; SELECT id, event_id, user_id, created_at FROM favorites ORDER BY id; SELECT id, event_id, user_id, parent_comment_id, body, deleted_at, updated_at FROM event_comments ORDER BY id; | J47: 10_要件定義書 4章・7章 | K47: 手動 | M47: OK | N47: 46309 | O47: 佐々木 | P47: ST-04-05〜07 の申込・お気に入り・コメントが残っていた。利用者詳細には、TD-04（開催済テスト）の申込も表示されている（テストデータとして登録した申込）。 | Q47: 45_テストエビデンス_総合.xlsx／ST-04
A48: ST-04-11 | B48: ST-04 利用者のアカウントを管理する（管理者の登録・降格、退会） | C48: 正常系 | D48: ST-04 利用者のアカウントを管理する（管理者の登録・降格、退会） | E48: 前のステップの結果 | F48: 【管理者】TD-02のSC-123を開く | G48: 申込者名が「退会済み利用者」と表示される（個人情報が表示されない） | H48: -（参照のみ） | I48: - | J48: 10_要件定義書 4章・7章 | K48: 手動 | M48: OK | N48: 46309 | O48: 佐々木 | Q48: 45_テストエビデンス_総合.xlsx／ST-04
A49: ST-04-12 | B49: ST-04 利用者のアカウントを管理する（管理者の登録・降格、退会） | C49: 正常系 | D49: ST-04 利用者のアカウントを管理する（管理者の登録・降格、退会） | E49: 前のステップの結果 | F49: 【管理者】SC-130で「CSVダウンロード」を押し、ファイルを開く | G49: TD-02の行の申込者名が「退会済み利用者」と出力されている | H49: -（参照のみ） | I49: - | J49: 10_要件定義書 4章・7章 | K49: 手動 | M49: OK | N49: 46309 | O49: 佐々木 | Q49: 45_テストエビデンス_総合.xlsx／ST-04
A50: ST-05-01 | B50: ST-05 パスワードを変更して利用を続ける | C50: 正常系 | D50: ST-05 パスワードを変更して利用を続ける | E50: 前のステップの結果 | F50: 【一般B】SC-010でgeneral2@example.comとTest1234を入力し「ログイン」を押す | G50: SC-020へ遷移する | H50: -（参照のみ） | I50: - | J50: 10_要件定義書 4章・7章 | K50: 手動 | M50: OK | N50: 46309 | O50: 佐々木 | Q50: 45_テストエビデンス_総合.xlsx／ST-05
A51: ST-05-02 | B51: ST-05 パスワードを変更して利用を続ける | C51: 正常系 | D51: ST-05 パスワードを変更して利用を続ける | E51: 前のステップの結果 | F51: 【一般B】共通ナビゲーションの「パスワード変更」を押す | G51: SC-011が表示される | H51: -（参照のみ） | I51: - | J51: 10_要件定義書 4章・7章 | K51: 手動 | M51: OK | N51: 46309 | O51: 佐々木 | P51: パスワード変更画面（/my/password）を開いた直後の画像は撮影が漏れたため、ST-05-03 の画像（同じ画面で変更を完了した状態）で、パスワード変更画面が表示されたことを確認した。 | Q51: 45_テストエビデンス_総合.xlsx／ST-05
...

Sheet 不具合一覧
A1: No | B1: テストID | C1: 事象 | D1: 再現手順 | E1: 期待結果 | F1: 実際の結果 | G1: Issue | H1: 状態 | I1: 修正PR | J1: 再テスト日 | K1: 再テスト結果
A2: 1 | B2: IT-CMN-N05（テストケース外の気づき） | C2: 存在しないURLを呼ぶと404ではなく500になる | D2: GET /favicon.ico、または X-User-Id: 1 で GET /api/nothing | E2: 404 | F2: 500「システムエラーが発生しました。時間をおいて再度お試しください」。ERRORログとスタックトレースが出力される | G2: #17 | H2: 修正済み（再確認OK） | J2: 46304 | K2: OK
A3: 2 | B3: IT-AP030-E07 | C3: 参加区分の無いイベントに他のイベントの区分IDを指定しても申込が登録される | D3: X-User-Id: 1 で POST /api/applications に {"eventId": 53, "ticketTypeId": 1} を送る（53は区分の無いイベント、1は別のイベントの区分） | E3: 404「指定された区分が見つかりません」（E-B-005）。applicationsは変更されない | F3: 201。ticketTypeIdがnullの申込として登録される | G3: #18 | H3: 修正済み（再テストOK） | J3: 46304 | K3: OK
A4: 3 | B4: IT-SC121-N05 | C4: 有効な申込があるイベントは、参加区分を変えなくても編集画面から保存できない | D4: 管理者で、受付済の申込がある「定員1テスト」（ID=53、区分なし）の編集画面を開き、場所を「会議室C」に変えて「保存」を押す | E4: SC-120へ遷移し、変更後の場所が表示される。events.placeが更新される | F4: 「区分に申込があるため変更できません」と表示され、保存できない。events.placeは変わらない | G4: #19 | H4: 修正済み（再テストOK） | J4: 46309 | K4: OK
